Workbook

Sheet Readme
D2: Performance Ranking by Index of Deviation of Reference Limits (PRIDe-RL)
D3: Readme — how to use the tool and navigate the worksheets
B5: Tool information and attribution
B6: Tool | F6: Performance Ranking by Index of Deviation of Reference Limits (PRIDe-RL)
B7: Version | F7: 1.0.0
B8: Release date | F8: 13 Feb 2025
B9: Author | F9: Alan Carvalho Dias
B10: ORCID | F10: https://orcid.org/0000-0002-7159-4593
B11: Corresponding e-mail | F11: alancdias@hotmail.com
B12: Website | F12: https://grupolabr.com
B13: Repository / DOI | F13: https://github.com/labrgrupo/Supplementary_Material_CCA_LabRI
B14: System requirements | F14: Microsoft Excel 365 or Excel 2021 (or later). The worksheet uses dynamic array functions (LET, SORT, SEQUENCE, TEXTJOIN, UNICHAR) that are unavailable in Excel 2016/2019 and may not behave identically in LibreOffice Calc.
B16: 1. What this tool does
B17: PRIDe-RL (Performance Ranking by Index of Deviation of Reference Limits) compares indirect methods for estimating reference limits — TML, refineR, TMC, reflimR and LabRI — against a comparative reference interval. For each analyte, every estimated lower (LRL) and upper (URL) reference limit is expressed as a deviation in units of the permissible difference (pD). These deviations are combined into four performance dimensions and a single PRIDe-RL score (0 to 1, higher is better), which is used to rank the methods.
B19: 2. Quick start — step by step
B20: Step 1 — Open 'Input Group 1' (real-world datasets) and/or 'Input Group 2' (simulated test cases). Both worksheets have the same structure.
B21: Step 2 — In cell G5, select the nominal coverage probability (0.90 or 0.80) from the drop-down list. The significance level (α), the quantile order and the standard normal critical value z (G6:G8) update automatically.
B22: Step 3 — From row 12 onwards, enter one analyte (or test case) per row: Test (B), Unit (C), sample size n (D), number of decimal places (E) and the comparative reference limits LRL and URL (F:G).
B23: Step 4 — Enter the LRL and URL estimated by each method: TML (V:W), refineR (Z:AA), TMC (AD:AE), reflimR (AH:AI) and LabRI (AL:AM).
B24: Step 5 — Columns H:T are calculated automatically (CVE, pCVA, median, pSDA, slope, intercept, pD and equivalence interval EI for each limit). The 1/0 columns next to each method indicate whether the estimate lies within the EI (1 = yes, 0 = no).
B25: Step 6 — Review the 'Heatmap' worksheet for a visual overview of the deviations, then the 'PRIDE-RL ranking' worksheet for the final scores and ranks.
B26: Tip — Leave unused cells empty (do not type 0). If the LRL is unknown or 0, the tool sets it at 15% of the URL for the CVE calculation. Abbreviations are explained below each input table.
B28: 3. Colour code
B29: Light blue cells | E29: User inputs — type or paste your data here.
B30: Light yellow cells | E30: Calculated automatically — do not overwrite (formulas).
B31: Heatmap: green / yellow | E31: Deviation within the equivalence interval (|d| ≤ 1 pD); yellow = close to its edge.
B32: Heatmap: orange / red | E32: Deviation outside the equivalence interval (|d| > 1 pD).
B34: 4. Worksheet guide — what each tab does (click a tab name to open it)
B35: Worksheet | E35: What it does | K35: What you do there
B36: Readme | E36: This guide: purpose of the tool, step-by-step instructions, colour code, worksheet guide and interpretation of the results. | K36: Read first.
B37: Input Group 1 | E37: Data entry and calculations for real-world datasets (12 analytes: AMY, Ca, LDH, TSH, FT4, ALT, GGT, RBC, Hb, WBC, LYM, PLT; rows 12–23). Derives CVE, pCVA, pSDA and the permissible difference (pD) for each reference limit, builds the equivalence interval (EI = RL ± pD), flags whether each method's estimate falls within the EI, and shows a preliminary ranking by % of limits within the EI (columns AQ:AV). | K37: Choose the coverage probability (G5) and enter/edit the light blue input cells: analyte data, comparative reference limits and each method's estimates.
B38: Input Group 2 | E38: Same structure and calculations as Input Group 1, applied to simulated test cases (15 rows: test cases evaluated at different sample sizes; rows 12–26). | K38: Same as Input Group 1.
B39: Heatmap | E39: Deviation of every method for every reference limit in pD units: d = (estimate − comparative RL) / pD. One row per limit (LRL and URL); rows 6–29 = Group 1, rows 30–59 = Group 2. Colours give a visual gestalt of method performance (|d| ≤ 1 = within the EI). Includes a legend at the bottom. | K39: Read only — fed automatically by the input worksheets.
B40: PRIDE-RL ranking | E40: Calculates the four performance dimensions (d1 Conformity, d2 Proximity, d3 Tail behaviour, d4 Severity), the PRIDe-RL score and the rank of each method for Group 1 (rows 5–12), Group 2 (rows 14–21) and globally, Group 1 + Group 2 (rows 23–30). 'Ord (tie-break)' gives a unique order when scores tie. | K40: Read only — check the Rank column (1 = best) and the PRIDE-RL score.
B41: PRIDe-RL scoring framework | E41: Illustrated explanation (figures) of the scoring framework and of each of the four dimensions d1–d4. | K41: Read to understand how the score is built.
B42: References | E42: Bibliography supporting the method (with links) and tool information: version, release date, author, ORCID, contact, repository/DOI and system requirements. | K42: Consult and cite.
B44: 5. How the PRIDe-RL score is calculated
B45: Deviation of each limit: d = (method estimate − comparative RL) / pD, where pD = z × pSDA at that limit (z depends on the coverage probability chosen in G5).
B46: d1 — Conformity = proportion of reference limits with |d| ≤ 1 (estimate within the equivalence interval).
B47: d2 — Proximity = 1 / (1 + mean |d|): rewards estimates that are close to the comparative limit.
...

Sheet Input Group 1
D2: Performance Ranking by Index of Deviation of Reference Limits (PRIDe-RL)
D3: A multidimensional framework for comparative evaluation and ranking of reference-limit estimation methods
B5: Nominal coverage probability (or confidence level) | G5: 0.9 | P5: 0.8
B6: Significance level (α) | G6: =1-IF(G5="",0.9,G5) -> 0.1 | P6: 0.9
B7: ="Cumulative probability (quantile order, "&IF(G5="","1 − α/2",SUBSTITUTE(ROUND(1-(1-G5)/2,4)&"",",","."))&")" -> Cumulative probability (quantile order, 0.95) | G7: =1-G6/2 -> 0.95 | H7: Interpretation of the standard normal quantile
B8: {="Standard normal quantile (critical value, z"&IF(G5="","₁₋α/₂",_xlfn.LET(_xlpm.p,ROUND(1-(1-G5)/2,4),_xlpm.d,SUBSTITUTE(_xlpm.p&"",",","."),_xlfn.TEXTJOIN("",1,IFERROR(_xlfn.UNICHAR(8320+MID(_xlpm.d,_xlfn.SEQUENCE(LEN(_xlpm.d)),1)),"."))))&")"} -> Standard normal quantile (critical value, z₀.₉₅) | G8: =_xlfn.NORM.S.INV(G7) -> 1.6448536 | H8: {=_xlfn.LET(_xlpm.cl,IF(G5="",0.9,G5),_xlpm.p,ROUND(1-(1-_xlpm.cl)/2,4),_xlpm.d,SUBSTITUTE(_xlpm.p&"",",","."),_xlpm.sub,_xlfn.TEXTJOIN("",1,IFERROR(_xlfn.UNICHAR(8320+MID(_xlpm.d,_xlfn.SEQUENCE(LEN(_xlpm.d)),1)),".")),"where z"&_xlpm.sub&" = "&SUBSTITUTE(FIXED(_xlfn.NORM.S.INV(_xlpm.p),4,TRUE)&"",",",".")&" is the standard normal quantile corresponding to a two-sided nominal coverage probability of "&SUBSTITUTE(ROUND(_xlpm.cl*100,2)&"",",",".")&"%.")} -> where z₀.₉₅ = 1.6449 is the standard normal quantile corresponding to a two-sided nominal coverage probability of 90%.
B10: Test | C10: Unit | D10: n | E10: Decimal places | F10: Comparative Reference | H10: CVE | I10: pCVA | J10: Med | K10: pSDA,Med | L10: Slope | M10: Intercept | N10: pSDA,LRL | O10: pDLRL | P10: EILRL | R10: pSDA,URL | S10: pDURL | T10: EIURL | V10: TML | X10: TML LRL within EILRL | Y10: TML URL within EIURL | Z10: refineR | AB10: refineR LRL within EILRL | AC10: refineR URL within EIURL | AD10: TMC | AF10: TMC LRL within EILRL | AG10: TMC URL within EIURL | AH10: reflimR | AJ10: reflimR LRL within EILRL | AK10: reflimR URL within EIURL | AL10: LabRI | AN10: LabRI LRL within EILRL | AO10: LabRI URL within EIURL
F11: LRL | G11: URL | V11: LRL | W11: URL | X11: 1 = yes / 0 = no | Y11: 1 = yes / 0 = no | Z11: LRL | AA11: URL | AB11: 1 = yes / 0 = no | AC11: 1 = yes / 0 = no | AD11: LRL | AE11: URL | AF11: 1 = yes / 0 = no | AG11: 1 = yes / 0 = no | AH11: LRL | AI11: URL | AJ11: 1 = yes / 0 = no | AK11: 1 = yes / 0 = no | AL11: LRL | AM11: URL | AN11: 1 = yes / 0 = no | AO11: 1 = yes / 0 = no
B12: AMY | C12: U/L | D12: 533 | E12: 0 | F12: 47 | G12: 164 | H12: =IFERROR(SQRT(EXP(((LN(G12)-LN(IF(OR(F12="",F12=0),IF(G12="","",0.15*G12),F12)))/3.92)^2)-1),"") -> 0.32708062 | I12: =IFERROR(((SQRT(H12*100-0.25))/100),"") -> 0.056971978 | J12: =IFERROR(EXP((IF(OR(F12="",F12=0),LN(G12*0.15),LN(F12))+LN(G12))/2),"") -> 87.795216 | K12: =IFERROR(I12*J12,"") -> 5.0018671 | L12: =IFERROR((K12-0.2*K12)/J12,"") -> 0.045577582 | M12: =IFERROR(0.2*K12,"") -> 1.0003734 | N12: =IFERROR(IF(F12="","",F12*L12+M12),"") -> 3.1425198 | O12: =IFERROR($G$8*N12,"") -> 5.168985 | P12: =IFERROR(CONCATENATE(ROUND(F12-O12,IF(E12="",3,E12))," to ",ROUND(F12+O12,IF(E12="",3,E12))),"") -> 42 to 52 | R12: =IFERROR(IF(G12="","",G12*L12+M12),"") -> 8.4750969 | S12: =IFERROR($G$8*R12,"") -> 13.940294 | T12: =IFERROR(CONCATENATE(ROUND(G12-S12,IF(E12="",3,E12))," to ",ROUND(G12+S12,IF(E12="",3,E12))),"") -> 150 to 178 | V12: 29.5 | W12: 151 | X12: =IF(OR($F12="",$V12=""),"",IF(AND(ROUND($V12,IF($E12="",3,$E12))>=ROUND($F12-$O12,IF($E12="",3,$E12)),ROUND($V12,IF($E12="",3,$E12))<=ROUND($F12+$O12,IF($E12="",3,$E12))),1,0)) -> 0 | Y12: =IF(OR($G12="",$W12=""),"",IF(AND(ROUND($W12,IF($E12="",3,$E12))>=ROUND($G12-$S12,IF($E12="",3,$E12)),ROUND($W12,IF($E12="",3,$E12))<=ROUND($G12+$S12,IF($E12="",3,$E12))),1,0)) -> 1 | Z12: 37.8 | AA12: 143 | AB12: =IF(OR($F12="",$Z12=""),"",IF(AND(ROUND($Z12,IF($E12="",3,$E12))>=ROUND($F12-$O12,IF($E12="",3,$E12)),ROUND($Z12,IF($E12="",3,$E12))<=ROUND($F12+$O12,IF($E12="",3,$E12))),1,0)) -> 0 | AC12: =IF(OR($G12="",$AA12=""),"",IF(AND(ROUND($AA12,IF($E12="",3,$E12))>=ROUND($G12-$S12,IF($E12="",3,$E12)),ROUND($AA12,IF($E12="",3,$E12))<=ROUND($G12+$S12,IF($E12="",3,$E12))),1,0)) -> 0 | AD12: 47.4 | AE12: 147 | AF12: =IF(OR($F12="",$AD12=""),"",IF(AND(ROUND($AD12,IF($E12="",3,$E12))>=ROUND($F12-$O12,IF($E12="",3,$E12)),ROUND($AD12,IF($E12="",3,$E12))<=ROUND($F12+$O12,IF($E12="",3,$E12))),1,0)) -> 1 | AG12: =IF(OR($G12="",$AE12=""),"",IF(AND(ROUND($AE12,IF($E12="",3,$E12))>=ROUND($G12-$S12,IF($E12="",3,$E12)),ROUND($AE12,IF($E12="",3,$E12))<=ROUND($G12+$S12,IF($E12="",3,$E12))),1,0)) -> 0 | AH12: 45.3 | AI12: 160.2 | AJ12: =IF(OR($F12="",$AH12=""),"",IF(AND(ROUND($AH12,IF($E12="",3,$E12))>=ROUND($F12-$O12,IF($E12="",3,$E12)),ROUND($AH12,IF($E12="",3,$E12))<=ROUND($F12+$O12,IF($E12="",3,$E12))),1,0)) -> 1 | AK12: =IF(OR($G12="",$AI12=""),"",IF(AND(ROUND($AI12,IF($E12="",3,$E12))>=ROUND($G12-$S12,IF($E12="",3,$E12)),ROUND($AI12,IF($E12="",3,$E12))<=ROUND($G12+$S12,IF($E12="",3,$E12))),1,0)) -> 1 | AL12: 45 | AM12: 165 | AN12: =IF(OR($F12="",$AL12=""),"",IF(AND(ROUND($AL12,IF($E12="",3,$E12))>=ROUND($F12-$O12,IF($E12="",3,$E12)),ROUND($AL12,IF($E12="",3,$E12))<=ROUND($F12+$O12,IF($E12="",3,$E12))),1,0)) -> 1 | AO12: =IF(OR($G12="",$AM12=""),"",IF(AND(ROUND($AM12,IF($E12="",3,$E12))>=ROUND($G12-$S12,IF($E12="",3,$E12)),ROUND($AM12,IF($E12="",3,$E12))<=ROUND($G12+$S12,IF($E12="",3,$E12))),1,0)) -> 1
B13: Ca | C13: mmol/L | D13: 533 | E13: 2 | F13: 2.19 | G13: 2.57 | H13: =IFERROR(SQRT(EXP(((LN(G13)-LN(IF(OR(F13="",F13=0),IF(G13="","",0.15*G13),F13)))/3.92)^2)-1),"") -> 0.040834445 | I13: =IFERROR(((SQRT(H13*100-0.25))/100),"") -> 0.019579184 | J13: =IFERROR(EXP((IF(OR(F13="",F13=0),LN(G13*0.15),LN(F13))+LN(G13))/2),"") -> 2.3724038 | K13: =IFERROR(I13*J13,"") -> 0.046449731 | L13: =IFERROR((K13-0.2*K13)/J13,"") -> 0.015663347 | M13: =IFERROR(0.2*K13,"") -> 0.0092899463 | N13: =IFERROR(IF(F13="","",F13*L13+M13),"") -> 0.043592677 | O13: =IFERROR($G$8*N13,"") -> 0.071703572 | P13: =IFERROR(CONCATENATE(ROUND(F13-O13,IF(E13="",3,E13))," to ",ROUND(F13+O13,IF(E13="",3,E13))),"") -> 2,12 to 2,26 | R13: =IFERROR(IF(G13="","",G13*L13+M13),"") -> 0.049544749 | S13: =IFERROR($G$8*R13,"") -> 0.081493859 | T13: =IFERROR(CONCATENATE(ROUND(G13-S13,IF(E13="",3,E13))," to ",ROUND(G13+S13,IF(E13="",3,E13))),"") -> 2,49 to 2,65 | V13: 2.19 | W13: 2.55 | X13: =IF(OR($F13="",$V13=""),"",IF(AND(ROUND($V13,IF($E13="",3,$E13))>=ROUND($F13-$O13,IF($E13="",3,$E13)),ROUND($V13,IF($E13="",3,$E13))<=ROUND($F13+$O13,IF($E13="",3,$E13))),1,0)) -> 1 | Y13: =IF(OR($G13="",$W13=""),"",IF(AND(ROUND($W13,IF($E13="",3,$E13))>=ROUND($G13-$S13,IF($E13="",3,$E13)),ROUND($W13,IF($E13="",3,$E13))<=ROUND($G13+$S13,IF($E13="",3,$E13))),1,0)) -> 1 | Z13: 2.21 | AA13: 2.51 | AB13: =IF(OR($F13="",$Z13=""),"",IF(AND(ROUND($Z13,IF($E13="",3,$E13))>=ROUND($F13-$O13,IF($E13="",3,$E13)),ROUND($Z13,IF($E13="",3,$E13))<=ROUND($F13+$O13,IF($E13="",3,$E13))),1,0)) -> 1 | AC13: =IF(OR($G13="",$AA13=""),"",IF(AND(ROUND($AA13,IF($E13="",3,$E13))>=ROUND($G13-$S13,IF($E13="",3,$E13)),ROUND($AA13,IF($E13="",3,$E13))<=ROUND($G13+$S13,IF($E13="",3,$E13))),1,0)) -> 1 | AD13: 2.19 | AE13: 2.55 | AF13: =IF(OR($F13="",$AD13=""),"",IF(AND(ROUND($AD13,IF($E13="",3,$E13))>=ROUND($F13-$O13,IF($E13="",3,$E13)),ROUND($AD13,IF($E13="",3,$E13))<=ROUND($F13+$O13,IF($E13="",3,$E13))),1,0)) -> 1 | AG13: =IF(OR($G13="",$AE13=""),"",IF(AND(ROUND($AE13,IF($E13="",3,$E13))>=ROUND($G13-$S13,IF($E13="",3,$E13)),ROUND($AE13,IF($E13="",3,$E13))<=ROUND($G13+$S13,IF($E13="",3,$E13))),1,0)) -> 1 | AH13: 2.19 | AI13: 2.54 | AJ13: =IF(OR($F13="",$AH13=""),"",IF(AND(ROUND($AH13,IF($E13="",3,$E13))>=ROUND($F13-$O13,IF($E13="",3,$E13)),ROUND($AH13,IF($E13="",3,$E13))<=ROUND($F13+$O13,IF($E13="",3,$E13))),1,0)) -> 1 | AK13: =IF(OR($G13="",$AI13=""),"",IF(AND(ROUND($AI13,IF($E13="",3,$E13))>=ROUND($G13-$S13,IF($E13="",3,$E13)),ROUND($AI13,IF($E13="",3,$E13))<=ROUND($G13+$S13,IF($E13="",3,$E13))),1,0)) -> 1 | AL13: 2.19 | AM13: 2.55 | AN13: =IF(OR($F13="",$AL13=""),"",IF(AND(ROUND($AL13,IF($E13="",3,$E13))>=ROUND($F13-$O13,IF($E13="",3,$E13)),ROUND($AL13,IF($E13="",3,$E13))<=ROUND($F13+$O13,IF($E13="",3,$E13))),1,0)) -> 1 | AO13: =IF(OR($G13="",$AM13=""),"",IF(AND(ROUND($AM13,IF($E13="",3,$E13))>=ROUND($G13-$S13,IF($E13="",3,$E13)),ROUND($AM13,IF($E13="",3,$E13))<=ROUND($G13+$S13,IF($E13="",3,$E13))),1,0)) -> 1
B14: LDH | C14: IU/L | D14: 533 | E14: 0 | F14: 138 | G14: 257 | H14: =IFERROR(SQRT(EXP(((LN(G14)-LN(IF(OR(F14="",F14=0),IF(G14="","",0.15*G14),F14)))/3.92)^2)-1),"") -> 0.1596313 | I14: =IFERROR(((SQRT(H14*100-0.25))/100),"") -> 0.039639791 | J14: =IFERROR(EXP((IF(OR(F14="",F14=0),LN(G14*0.15),LN(F14))+LN(G14))/2),"") -> 188.32419 | K14: =IFERROR(I14*J14,"") -> 7.4651314 | L14: =IFERROR((K14-0.2*K14)/J14,"") -> 0.031711833 | M14: =IFERROR(0.2*K14,"") -> 1.4930263 | N14: =IFERROR(IF(F14="","",F14*L14+M14),"") -> 5.8692592 | O14: =IFERROR($G$8*N14,"") -> 9.6540722 | P14: =IFERROR(CONCATENATE(ROUND(F14-O14,IF(E14="",3,E14))," to ",ROUND(F14+O14,IF(E14="",3,E14))),"") -> 128 to 148 | R14: =IFERROR(IF(G14="","",G14*L14+M14),"") -> 9.6429672 | S14: =IFERROR($G$8*R14,"") -> 15.86127 | T14: =IFERROR(CONCATENATE(ROUND(G14-S14,IF(E14="",3,E14))," to ",ROUND(G14+S14,IF(E14="",3,E14))),"") -> 241 to 273 | V14: 134 | W14: 233 | X14: =IF(OR($F14="",$V14=""),"",IF(AND(ROUND($V14,IF($E14="",3,$E14))>=ROUND($F14-$O14,IF($E14="",3,$E14)),ROUND($V14,IF($E14="",3,$E14))<=ROUND($F14+$O14,IF($E14="",3,$E14))),1,0)) -> 1 | Y14: =IF(OR($G14="",$W14=""),"",IF(AND(ROUND($W14,IF($E14="",3,$E14))>=ROUND($G14-$S14,IF($E14="",3,$E14)),ROUND($W14,IF($E14="",3,$E14))<=ROUND($G14+$S14,IF($E14="",3,$E14))),1,0)) -> 0 | Z14: 138 | AA14: 233 | AB14: =IF(OR($F14="",$Z14=""),"",IF(AND(ROUND($Z14,IF($E14="",3,$E14))>=ROUND($F14-$O14,IF($E14="",3,$E14)),ROUND($Z14,IF($E14="",3,$E14))<=ROUND($F14+$O14,IF($E14="",3,$E14))),1,0)) -> 1 | AC14: =IF(OR($G14="",$AA14=""),"",IF(AND(ROUND($AA14,IF($E14="",3,$E14))>=ROUND($G14-$S14,IF($E14="",3,$E14)),ROUND($AA14,IF($E14="",3,$E14))<=ROUND($G14+$S14,IF($E14="",3,$E14))),1,0)) -> 0 | AD14: 140 | AE14: 241 | AF14: =IF(OR($F14="",$AD14=""),"",IF(AND(ROUND($AD14,IF($E14="",3,$E14))>=ROUND($F14-$O14,IF($E14="",3,$E14)),ROUND($AD14,IF($E14="",3,$E14))<=ROUND($F14+$O14,IF($E14="",3,$E14))),1,0)) -> 1 | AG14: =IF(OR($G14="",$AE14=""),"",IF(AND(ROUND($AE14,IF($E14="",3,$E14))>=ROUND($G14-$S14,IF($E14="",3,$E14)),ROUND($AE14,IF($E14="",3,$E14))<=ROUND($G14+$S14,IF($E14="",3,$E14))),1,0)) -> 1 | AH14: 140 | AI14: 251 | AJ14: =IF(OR($F14="",$AH14=""),"",IF(AND(ROUND($AH14,IF($E14="",3,$E14))>=ROUND($F14-$O14,IF($E14="",3,$E14)),ROUND($AH14,IF($E14="",3,$E14))<=ROUND($F14+$O14,IF($E14="",3,$E14))),1,0)) -> 1 | AK14: =IF(OR($G14="",$AI14=""),"",IF(AND(ROUND($AI14,IF($E14="",3,$E14))>=ROUND($G14-$S14,IF($E14="",3,$E14)),ROUND($AI14,IF($E14="",3,$E14))<=ROUND($G14+$S14,IF($E14="",3,$E14))),1,0)) -> 1 | AL14: 139 | AM14: 247 | AN14: =IF(OR($F14="",$AL14=""),"",IF(AND(ROUND($AL14,IF($E14="",3,$E14))>=ROUND($F14-$O14,IF($E14="",3,$E14)),ROUND($AL14,IF($E14="",3,$E14))<=ROUND($F14+$O14,IF($E14="",3,$E14))),1,0)) -> 1 | AO14: =IF(OR($G14="",$AM14=""),"",IF(AND(ROUND($AM14,IF($E14="",3,$E14))>=ROUND($G14-$S14,IF($E14="",3,$E14)),ROUND($AM14,IF($E14="",3,$E14))<=ROUND($G14+$S14,IF($E14="",3,$E14))),1,0)) -> 1
B15: TSH | C15: mIU/L | D15: 533 | E15: 2 | F15: 0.61 | G15: 4.86 | H15: =IFERROR(SQRT(EXP(((LN(G15)-LN(IF(OR(F15="",F15=0),IF(G15="","",0.15*G15),F15)))/3.92)^2)-1),"") -> 0.56877997 | I15: =IFERROR(((SQRT(H15*100-0.25))/100),"") -> 0.075251576 | J15: =IFERROR(EXP((IF(OR(F15="",F15=0),LN(G15*0.15),LN(F15))+LN(G15))/2),"") -> 1.7218014 | K15: =IFERROR(I15*J15,"") -> 0.12956827 | L15: =IFERROR((K15-0.2*K15)/J15,"") -> 0.060201261 | M15: =IFERROR(0.2*K15,"") -> 0.025913654 | N15: =IFERROR(IF(F15="","",F15*L15+M15),"") -> 0.062636423 | O15: =IFERROR($G$8*N15,"") -> 0.10302775 | P15: =IFERROR(CONCATENATE(ROUND(F15-O15,IF(E15="",3,E15))," to ",ROUND(F15+O15,IF(E15="",3,E15))),"") -> 0,51 to 0,71 | R15: =IFERROR(IF(G15="","",G15*L15+M15),"") -> 0.31849178 | S15: =IFERROR($G$8*R15,"") -> 0.52387236 | T15: =IFERROR(CONCATENATE(ROUND(G15-S15,IF(E15="",3,E15))," to ",ROUND(G15+S15,IF(E15="",3,E15))),"") -> 4,34 to 5,38 | V15: 0.6 | W15: 4.03 | X15: =IF(OR($F15="",$V15=""),"",IF(AND(ROUND($V15,IF($E15="",3,$E15))>=ROUND($F15-$O15,IF($E15="",3,$E15)),ROUND($V15,IF($E15="",3,$E15))<=ROUND($F15+$O15,IF($E15="",3,$E15))),1,0)) -> 1 | Y15: =IF(OR($G15="",$W15=""),"",IF(AND(ROUND($W15,IF($E15="",3,$E15))>=ROUND($G15-$S15,IF($E15="",3,$E15)),ROUND($W15,IF($E15="",3,$E15))<=ROUND($G15+$S15,IF($E15="",3,$E15))),1,0)) -> 0 | Z15: 0.52 | AA15: 3.22 | AB15: =IF(OR($F15="",$Z15=""),"",IF(AND(ROUND($Z15,IF($E15="",3,$E15))>=ROUND($F15-$O15,IF($E15="",3,$E15)),ROUND($Z15,IF($E15="",3,$E15))<=ROUND($F15+$O15,IF($E15="",3,$E15))),1,0)) -> 1 | AC15: =IF(OR($G15="",$AA15=""),"",IF(AND(ROUND($AA15,IF($E15="",3,$E15))>=ROUND($G15-$S15,IF($E15="",3,$E15)),ROUND($AA15,IF($E15="",3,$E15))<=ROUND($G15+$S15,IF($E15="",3,$E15))),1,0)) -> 0 | AD15: 0.59 | AE15: 4.63 | AF15: =IF(OR($F15="",$AD15=""),"",IF(AND(ROUND($AD15,IF($E15="",3,$E15))>=ROUND($F15-$O15,IF($E15="",3,$E15)),ROUND($AD15,IF($E15="",3,$E15))<=ROUND($F15+$O15,IF($E15="",3,$E15))),1,0)) -> 1 | AG15: =IF(OR($G15="",$AE15=""),"",IF(AND(ROUND($AE15,IF($E15="",3,$E15))>=ROUND($G15-$S15,IF($E15="",3,$E15)),ROUND($AE15,IF($E15="",3,$E15))<=ROUND($G15+$S15,IF($E15="",3,$E15))),1,0)) -> 1 | AH15: 0.55 | AI15: 4.59 | AJ15: =IF(OR($F15="",$AH15=""),"",IF(AND(ROUND($AH15,IF($E15="",3,$E15))>=ROUND($F15-$O15,IF($E15="",3,$E15)),ROUND($AH15,IF($E15="",3,$E15))<=ROUND($F15+$O15,IF($E15="",3,$E15))),1,0)) -> 1 | AK15: =IF(OR($G15="",$AI15=""),"",IF(AND(ROUND($AI15,IF($E15="",3,$E15))>=ROUND($G15-$S15,IF($E15="",3,$E15)),ROUND($AI15,IF($E15="",3,$E15))<=ROUND($G15+$S15,IF($E15="",3,$E15))),1,0)) -> 1 | AL15: 0.54 | AM15: 4.76 | AN15: =IF(OR($F15="",$AL15=""),"",IF(AND(ROUND($AL15,IF($E15="",3,$E15))>=ROUND($F15-$O15,IF($E15="",3,$E15)),ROUND($AL15,IF($E15="",3,$E15))<=ROUND($F15+$O15,IF($E15="",3,$E15))),1,0)) -> 1 | AO15: =IF(OR($G15="",$AM15=""),"",IF(AND(ROUND($AM15,IF($E15="",3,$E15))>=ROUND($G15-$S15,IF($E15="",3,$E15)),ROUND($AM15,IF($E15="",3,$E15))<=ROUND($G15+$S15,IF($E15="",3,$E15))),1,0)) -> 1
B16: FT4 | C16: pmol/L | D16: 533 | E16: 1 | F16: 7.8 | G16: 14.1 | H16: =IFERROR(SQRT(EXP(((LN(G16)-LN(IF(OR(F16="",F16=0),IF(G16="","",0.15*G16),F16)))/3.92)^2)-1),"") -> 0.15189885 | I16: =IFERROR(((SQRT(H16*100-0.25))/100),"") -> 0.038652148 | J16: =IFERROR(EXP((IF(OR(F16="",F16=0),LN(G16*0.15),LN(F16))+LN(G16))/2),"") -> 10.487135 | K16: =IFERROR(I16*J16,"") -> 0.40535029 | L16: =IFERROR((K16-0.2*K16)/J16,"") -> 0.030921718 | M16: =IFERROR(0.2*K16,"") -> 0.081070058 | N16: =IFERROR(IF(F16="","",F16*L16+M16),"") -> 0.32225946 | O16: =IFERROR($G$8*N16,"") -> 0.53006964 | P16: =IFERROR(CONCATENATE(ROUND(F16-O16,IF(E16="",3,E16))," to ",ROUND(F16+O16,IF(E16="",3,E16))),"") -> 7,3 to 8,3 | R16: =IFERROR(IF(G16="","",G16*L16+M16),"") -> 0.51706628 | S16: =IFERROR($G$8*R16,"") -> 0.85049835 | T16: =IFERROR(CONCATENATE(ROUND(G16-S16,IF(E16="",3,E16))," to ",ROUND(G16+S16,IF(E16="",3,E16))),"") -> 13,2 to 15 | V16: 6.76 | W16: 13.9 | X16: =IF(OR($F16="",$V16=""),"",IF(AND(ROUND($V16,IF($E16="",3,$E16))>=ROUND($F16-$O16,IF($E16="",3,$E16)),ROUND($V16,IF($E16="",3,$E16))<=ROUND($F16+$O16,IF($E16="",3,$E16))),1,0)) -> 0 | Y16: =IF(OR($G16="",$W16=""),"",IF(AND(ROUND($W16,IF($E16="",3,$E16))>=ROUND($G16-$S16,IF($E16="",3,$E16)),ROUND($W16,IF($E16="",3,$E16))<=ROUND($G16+$S16,IF($E16="",3,$E16))),1,0)) -> 1 | Z16: 7.92 | AA16: 13.3 | AB16: =IF(OR($F16="",$Z16=""),"",IF(AND(ROUND($Z16,IF($E16="",3,$E16))>=ROUND($F16-$O16,IF($E16="",3,$E16)),ROUND($Z16,IF($E16="",3,$E16))<=ROUND($F16+$O16,IF($E16="",3,$E16))),1,0)) -> 1 | AC16: =IF(OR($G16="",$AA16=""),"",IF(AND(ROUND($AA16,IF($E16="",3,$E16))>=ROUND($G16-$S16,IF($E16="",3,$E16)),ROUND($AA16,IF($E16="",3,$E16))<=ROUND($G16+$S16,IF($E16="",3,$E16))),1,0)) -> 1 | AD16: 7.54 | AE16: 13.8 | AF16: =IF(OR($F16="",$AD16=""),"",IF(AND(ROUND($AD16,IF($E16="",3,$E16))>=ROUND($F16-$O16,IF($E16="",3,$E16)),ROUND($AD16,IF($E16="",3,$E16))<=ROUND($F16+$O16,IF($E16="",3,$E16))),1,0)) -> 1 | AG16: =IF(OR($G16="",$AE16=""),"",IF(AND(ROUND($AE16,IF($E16="",3,$E16))>=ROUND($G16-$S16,IF($E16="",3,$E16)),ROUND($AE16,IF($E16="",3,$E16))<=ROUND($G16+$S16,IF($E16="",3,$E16))),1,0)) -> 1 | AH16: 7.9 | AI16: 14.1 | AJ16: =IF(OR($F16="",$AH16=""),"",IF(AND(ROUND($AH16,IF($E16="",3,$E16))>=ROUND($F16-$O16,IF($E16="",3,$E16)),ROUND($AH16,IF($E16="",3,$E16))<=ROUND($F16+$O16,IF($E16="",3,$E16))),1,0)) -> 1 | AK16: =IF(OR($G16="",$AI16=""),"",IF(AND(ROUND($AI16,IF($E16="",3,$E16))>=ROUND($G16-$S16,IF($E16="",3,$E16)),ROUND($AI16,IF($E16="",3,$E16))<=ROUND($G16+$S16,IF($E16="",3,$E16))),1,0)) -> 1 | AL16: 7.5 | AM16: 13.7 | AN16: =IF(OR($F16="",$AL16=""),"",IF(AND(ROUND($AL16,IF($E16="",3,$E16))>=ROUND($F16-$O16,IF($E16="",3,$E16)),ROUND($AL16,IF($E16="",3,$E16))<=ROUND($F16+$O16,IF($E16="",3,$E16))),1,0)) -> 1 | AO16: =IF(OR($G16="",$AM16=""),"",IF(AND(ROUND($AM16,IF($E16="",3,$E16))>=ROUND($G16-$S16,IF($E16="",3,$E16)),ROUND($AM16,IF($E16="",3,$E16))<=ROUND($G16+$S16,IF($E16="",3,$E16))),1,0)) -> 1
B17: ALT | C17: U/L | D17: 874 | E17: 1 | F17: 6.6 | G17: 34.5 | H17: =IFERROR(SQRT(EXP(((LN(G17)-LN(IF(OR(F17="",F17=0),IF(G17="","",0.15*G17),F17)))/3.92)^2)-1),"") -> 0.44140183 | I17: =IFERROR(((SQRT(H17*100-0.25))/100),"") -> 0.066249666 | J17: =IFERROR(EXP((IF(OR(F17="",F17=0),LN(G17*0.15),LN(F17))+LN(G17))/2),"") -> 15.089732 | K17: =IFERROR(I17*J17,"") -> 0.99968968 | L17: =IFERROR((K17-0.2*K17)/J17,"") -> 0.052999733 | M17: =IFERROR(0.2*K17,"") -> 0.19993794 | N17: =IFERROR(IF(F17="","",F17*L17+M17),"") -> 0.54973617 | O17: =IFERROR($G$8*N17,"") -> 0.90423554 | P17: =IFERROR(CONCATENATE(ROUND(F17-O17,IF(E17="",3,E17))," to ",ROUND(F17+O17,IF(E17="",3,E17))),"") -> 5,7 to 7,5 | R17: =IFERROR(IF(G17="","",G17*L17+M17),"") -> 2.0284287 | S17: =IFERROR($G$8*R17,"") -> 3.3364683 | T17: =IFERROR(CONCATENATE(ROUND(G17-S17,IF(E17="",3,E17))," to ",ROUND(G17+S17,IF(E17="",3,E17))),"") -> 31,2 to 37,8 | V17: 5.7 | W17: 35.5 | X17: =IF(OR($F17="",$V17=""),"",IF(AND(ROUND($V17,IF($E17="",3,$E17))>=ROUND($F17-$O17,IF($E17="",3,$E17)),ROUND($V17,IF($E17="",3,$E17))<=ROUND($F17+$O17,IF($E17="",3,$E17))),1,0)) -> 1 | Y17: =IF(OR($G17="",$W17=""),"",IF(AND(ROUND($W17,IF($E17="",3,$E17))>=ROUND($G17-$S17,IF($E17="",3,$E17)),ROUND($W17,IF($E17="",3,$E17))<=ROUND($G17+$S17,IF($E17="",3,$E17))),1,0)) -> 1 | Z17: 8.87 | AA17: 34.7 | AB17: =IF(OR($F17="",$Z17=""),"",IF(AND(ROUND($Z17,IF($E17="",3,$E17))>=ROUND($F17-$O17,IF($E17="",3,$E17)),ROUND($Z17,IF($E17="",3,$E17))<=ROUND($F17+$O17,IF($E17="",3,$E17))),1,0)) -> 0 | AC17: =IF(OR($G17="",$AA17=""),"",IF(AND(ROUND($AA17,IF($E17="",3,$E17))>=ROUND($G17-$S17,IF($E17="",3,$E17)),ROUND($AA17,IF($E17="",3,$E17))<=ROUND($G17+$S17,IF($E17="",3,$E17))),1,0)) -> 1 | AD17: 9.94 | AE17: 34.2 | AF17: =IF(OR($F17="",$AD17=""),"",IF(AND(ROUND($AD17,IF($E17="",3,$E17))>=ROUND($F17-$O17,IF($E17="",3,$E17)),ROUND($AD17,IF($E17="",3,$E17))<=ROUND($F17+$O17,IF($E17="",3,$E17))),1,0)) -> 0 | AG17: =IF(OR($G17="",$AE17=""),"",IF(AND(ROUND($AE17,IF($E17="",3,$E17))>=ROUND($G17-$S17,IF($E17="",3,$E17)),ROUND($AE17,IF($E17="",3,$E17))<=ROUND($G17+$S17,IF($E17="",3,$E17))),1,0)) -> 1 | AH17: 5.9 | AI17: 35 | AJ17: =IF(OR($F17="",$AH17=""),"",IF(AND(ROUND($AH17,IF($E17="",3,$E17))>=ROUND($F17-$O17,IF($E17="",3,$E17)),ROUND($AH17,IF($E17="",3,$E17))<=ROUND($F17+$O17,IF($E17="",3,$E17))),1,0)) -> 1 | AK17: =IF(OR($G17="",$AI17=""),"",IF(AND(ROUND($AI17,IF($E17="",3,$E17))>=ROUND($G17-$S17,IF($E17="",3,$E17)),ROUND($AI17,IF($E17="",3,$E17))<=ROUND($G17+$S17,IF($E17="",3,$E17))),1,0)) -> 1 | AL17: 6.7 | AM17: 35.4 | AN17: =IF(OR($F17="",$AL17=""),"",IF(AND(ROUND($AL17,IF($E17="",3,$E17))>=ROUND($F17-$O17,IF($E17="",3,$E17)),ROUND($AL17,IF($E17="",3,$E17))<=ROUND($F17+$O17,IF($E17="",3,$E17))),1,0)) -> 1 | AO17: =IF(OR($G17="",$AM17=""),"",IF(AND(ROUND($AM17,IF($E17="",3,$E17))>=ROUND($G17-$S17,IF($E17="",3,$E17)),ROUND($AM17,IF($E17="",3,$E17))<=ROUND($G17+$S17,IF($E17="",3,$E17))),1,0)) -> 1
B18: GGT | C18: U/L | D18: 874 | E18: 2 | F18: 12.22 | G18: 51.71 | H18: =IFERROR(SQRT(EXP(((LN(G18)-LN(IF(OR(F18="",F18=0),IF(G18="","",0.15*G18),F18)))/3.92)^2)-1),"") -> 0.38082263 | I18: =IFERROR(((SQRT(H18*100-0.25))/100),"") -> 0.061507937 | J18: =IFERROR(EXP((IF(OR(F18="",F18=0),LN(G18*0.15),LN(F18))+LN(G18))/2),"") -> 25.137546 | K18: =IFERROR(I18*J18,"") -> 1.5461586 | L18: =IFERROR((K18-0.2*K18)/J18,"") -> 0.04920635 | M18: =IFERROR(0.2*K18,"") -> 0.30923171 | N18: =IFERROR(IF(F18="","",F18*L18+M18),"") -> 0.91053331 | O18: =IFERROR($G$8*N18,"") -> 1.497694 | P18: =IFERROR(CONCATENATE(ROUND(F18-O18,IF(E18="",3,E18))," to ",ROUND(F18+O18,IF(E18="",3,E18))),"") -> 10,72 to 13,72 | R18: =IFERROR(IF(G18="","",G18*L18+M18),"") -> 2.853692 | S18: =IFERROR($G$8*R18,"") -> 4.6939057 | T18: =IFERROR(CONCATENATE(ROUND(G18-S18,IF(E18="",3,E18))," to ",ROUND(G18+S18,IF(E18="",3,E18))),"") -> 47,02 to 56,4 | V18: 11.5 | W18: 47.7 | X18: =IF(OR($F18="",$V18=""),"",IF(AND(ROUND($V18,IF($E18="",3,$E18))>=ROUND($F18-$O18,IF($E18="",3,$E18)),ROUND($V18,IF($E18="",3,$E18))<=ROUND($F18+$O18,IF($E18="",3,$E18))),1,0)) -> 1 | Y18: =IF(OR($G18="",$W18=""),"",IF(AND(ROUND($W18,IF($E18="",3,$E18))>=ROUND($G18-$S18,IF($E18="",3,$E18)),ROUND($W18,IF($E18="",3,$E18))<=ROUND($G18+$S18,IF($E18="",3,$E18))),1,0)) -> 1 | Z18: 19.3 | AA18: 52.5 | AB18: =IF(OR($F18="",$Z18=""),"",IF(AND(ROUND($Z18,IF($E18="",3,$E18))>=ROUND($F18-$O18,IF($E18="",3,$E18)),ROUND($Z18,IF($E18="",3,$E18))<=ROUND($F18+$O18,IF($E18="",3,$E18))),1,0)) -> 0 | AC18: =IF(OR($G18="",$AA18=""),"",IF(AND(ROUND($AA18,IF($E18="",3,$E18))>=ROUND($G18-$S18,IF($E18="",3,$E18)),ROUND($AA18,IF($E18="",3,$E18))<=ROUND($G18+$S18,IF($E18="",3,$E18))),1,0)) -> 1 | AD18: 12.2 | AE18: 47.1 | AF18: =IF(OR($F18="",$AD18=""),"",IF(AND(ROUND($AD18,IF($E18="",3,$E18))>=ROUND($F18-$O18,IF($E18="",3,$E18)),ROUND($AD18,IF($E18="",3,$E18))<=ROUND($F18+$O18,IF($E18="",3,$E18))),1,0)) -> 1 | AG18: =IF(OR($G18="",$AE18=""),"",IF(AND(ROUND($AE18,IF($E18="",3,$E18))>=ROUND($G18-$S18,IF($E18="",3,$E18)),ROUND($AE18,IF($E18="",3,$E18))<=ROUND($G18+$S18,IF($E18="",3,$E18))),1,0)) -> 1 | AH18: 11.6 | AI18: 47.9 | AJ18: =IF(OR($F18="",$AH18=""),"",IF(AND(ROUND($AH18,IF($E18="",3,$E18))>=ROUND($F18-$O18,IF($E18="",3,$E18)),ROUND($AH18,IF($E18="",3,$E18))<=ROUND($F18+$O18,IF($E18="",3,$E18))),1,0)) -> 1 | AK18: =IF(OR($G18="",$AI18=""),"",IF(AND(ROUND($AI18,IF($E18="",3,$E18))>=ROUND($G18-$S18,IF($E18="",3,$E18)),ROUND($AI18,IF($E18="",3,$E18))<=ROUND($G18+$S18,IF($E18="",3,$E18))),1,0)) -> 1 | AL18: 12.27 | AM18: 50.02 | AN18: =IF(OR($F18="",$AL18=""),"",IF(AND(ROUND($AL18,IF($E18="",3,$E18))>=ROUND($F18-$O18,IF($E18="",3,$E18)),ROUND($AL18,IF($E18="",3,$E18))<=ROUND($F18+$O18,IF($E18="",3,$E18))),1,0)) -> 1 | AO18: =IF(OR($G18="",$AM18=""),"",IF(AND(ROUND($AM18,IF($E18="",3,$E18))>=ROUND($G18-$S18,IF($E18="",3,$E18)),ROUND($AM18,IF($E18="",3,$E18))<=ROUND($G18+$S18,IF($E18="",3,$E18))),1,0)) -> 1 | AQ18: Performance ranking
B19: RBC | C19: 10^6/μL | D19: 992 | E19: 2 | F19: 3.97 | G19: 6.28 | H19: =IFERROR(SQRT(EXP(((LN(G19)-LN(IF(OR(F19="",F19=0),IF(G19="","",0.15*G19),F19)))/3.92)^2)-1),"") -> 0.11739224 | I19: =IFERROR(((SQRT(H19*100-0.25))/100),"") -> 0.033895758 | J19: =IFERROR(EXP((IF(OR(F19="",F19=0),LN(G19*0.15),LN(F19))+LN(G19))/2),"") -> 4.9931553 | K19: =IFERROR(I19*J19,"") -> 0.16924678 | L19: =IFERROR((K19-0.2*K19)/J19,"") -> 0.027116606 | M19: =IFERROR(0.2*K19,"") -> 0.033849357 | N19: =IFERROR(IF(F19="","",F19*L19+M19),"") -> 0.14150228 | O19: =IFERROR($G$8*N19,"") -> 0.23275054 | P19: =IFERROR(CONCATENATE(ROUND(F19-O19,IF(E19="",3,E19))," to ",ROUND(F19+O19,IF(E19="",3,E19))),"") -> 3,74 to 4,2 | R19: =IFERROR(IF(G19="","",G19*L19+M19),"") -> 0.20414164 | S19: =IFERROR($G$8*R19,"") -> 0.33578312 | T19: =IFERROR(CONCATENATE(ROUND(G19-S19,IF(E19="",3,E19))," to ",ROUND(G19+S19,IF(E19="",3,E19))),"") -> 5,94 to 6,62 | V19: 3.77 | W19: 6.19 | X19: =IF(OR($F19="",$V19=""),"",IF(AND(ROUND($V19,IF($E19="",3,$E19))>=ROUND($F19-$O19,IF($E19="",3,$E19)),ROUND($V19,IF($E19="",3,$E19))<=ROUND($F19+$O19,IF($E19="",3,$E19))),1,0)) -> 1 | Y19: =IF(OR($G19="",$W19=""),"",IF(AND(ROUND($W19,IF($E19="",3,$E19))>=ROUND($G19-$S19,IF($E19="",3,$E19)),ROUND($W19,IF($E19="",3,$E19))<=ROUND($G19+$S19,IF($E19="",3,$E19))),1,0)) -> 1 | Z19: 4.05 | AA19: 6.32 | AB19: =IF(OR($F19="",$Z19=""),"",IF(AND(ROUND($Z19,IF($E19="",3,$E19))>=ROUND($F19-$O19,IF($E19="",3,$E19)),ROUND($Z19,IF($E19="",3,$E19))<=ROUND($F19+$O19,IF($E19="",3,$E19))),1,0)) -> 1 | AC19: =IF(OR($G19="",$AA19=""),"",IF(AND(ROUND($AA19,IF($E19="",3,$E19))>=ROUND($G19-$S19,IF($E19="",3,$E19)),ROUND($AA19,IF($E19="",3,$E19))<=ROUND($G19+$S19,IF($E19="",3,$E19))),1,0)) -> 1 | AD19: 3.95 | AE19: 6.2 | AF19: =IF(OR($F19="",$AD19=""),"",IF(AND(ROUND($AD19,IF($E19="",3,$E19))>=ROUND($F19-$O19,IF($E19="",3,$E19)),ROUND($AD19,IF($E19="",3,$E19))<=ROUND($F19+$O19,IF($E19="",3,$E19))),1,0)) -> 1 | AG19: =IF(OR($G19="",$AE19=""),"",IF(AND(ROUND($AE19,IF($E19="",3,$E19))>=ROUND($G19-$S19,IF($E19="",3,$E19)),ROUND($AE19,IF($E19="",3,$E19))<=ROUND($G19+$S19,IF($E19="",3,$E19))),1,0)) -> 1 | AH19: 3.77 | AI19: 6.24 | AJ19: =IF(OR($F19="",$AH19=""),"",IF(AND(ROUND($AH19,IF($E19="",3,$E19))>=ROUND($F19-$O19,IF($E19="",3,$E19)),ROUND($AH19,IF($E19="",3,$E19))<=ROUND($F19+$O19,IF($E19="",3,$E19))),1,0)) -> 1 | AK19: =IF(OR($G19="",$AI19=""),"",IF(AND(ROUND($AI19,IF($E19="",3,$E19))>=ROUND($G19-$S19,IF($E19="",3,$E19)),ROUND($AI19,IF($E19="",3,$E19))<=ROUND($G19+$S19,IF($E19="",3,$E19))),1,0)) -> 1 | AL19: 3.97 | AM19: 6.25 | AN19: =IF(OR($F19="",$AL19=""),"",IF(AND(ROUND($AL19,IF($E19="",3,$E19))>=ROUND($F19-$O19,IF($E19="",3,$E19)),ROUND($AL19,IF($E19="",3,$E19))<=ROUND($F19+$O19,IF($E19="",3,$E19))),1,0)) -> 1 | AO19: =IF(OR($G19="",$AM19=""),"",IF(AND(ROUND($AM19,IF($E19="",3,$E19))>=ROUND($G19-$S19,IF($E19="",3,$E19)),ROUND($AM19,IF($E19="",3,$E19))<=ROUND($G19+$S19,IF($E19="",3,$E19))),1,0)) -> 1 | AQ19: Method | AR19: Overall % of RLs within the EI | AS19: Rank | AT19: LRLs within EI / total | AU19: URLs within EI / total | AV19: Total within EI / total possible
B20: Hb | C20: g/dL | D20: 992 | E20: 2 | F20: 10.6 | G20: 17.34 | H20: =IFERROR(SQRT(EXP(((LN(G20)-LN(IF(OR(F20="",F20=0),IF(G20="","",0.15*G20),F20)))/3.92)^2)-1),"") -> 0.12604792 | I20: =IFERROR(((SQRT(H20*100-0.25))/100),"") -> 0.035149385 | J20: =IFERROR(EXP((IF(OR(F20="",F20=0),LN(G20*0.15),LN(F20))+LN(G20))/2),"") -> 13.557433 | K20: =IFERROR(I20*J20,"") -> 0.47653544 | L20: =IFERROR((K20-0.2*K20)/J20,"") -> 0.028119508 | M20: =IFERROR(0.2*K20,"") -> 0.095307088 | N20: =IFERROR(IF(F20="","",F20*L20+M20),"") -> 0.39337387 | O20: =IFERROR($G$8*N20,"") -> 0.64704244 | P20: =IFERROR(CONCATENATE(ROUND(F20-O20,IF(E20="",3,E20))," to ",ROUND(F20+O20,IF(E20="",3,E20))),"") -> 9,95 to 11,25 | R20: =IFERROR(IF(G20="","",G20*L20+M20),"") -> 0.58289935 | S20: =IFERROR($G$8*R20,"") -> 0.95878412 | T20: =IFERROR(CONCATENATE(ROUND(G20-S20,IF(E20="",3,E20))," to ",ROUND(G20+S20,IF(E20="",3,E20))),"") -> 16,38 to 18,3 | V20: 10.8 | W20: 18.9 | X20: =IF(OR($F20="",$V20=""),"",IF(AND(ROUND($V20,IF($E20="",3,$E20))>=ROUND($F20-$O20,IF($E20="",3,$E20)),ROUND($V20,IF($E20="",3,$E20))<=ROUND($F20+$O20,IF($E20="",3,$E20))),1,0)) -> 1 | Y20: =IF(OR($G20="",$W20=""),"",IF(AND(ROUND($W20,IF($E20="",3,$E20))>=ROUND($G20-$S20,IF($E20="",3,$E20)),ROUND($W20,IF($E20="",3,$E20))<=ROUND($G20+$S20,IF($E20="",3,$E20))),1,0)) -> 0 | Z20: 11 | AA20: 17.2 | AB20: =IF(OR($F20="",$Z20=""),"",IF(AND(ROUND($Z20,IF($E20="",3,$E20))>=ROUND($F20-$O20,IF($E20="",3,$E20)),ROUND($Z20,IF($E20="",3,$E20))<=ROUND($F20+$O20,IF($E20="",3,$E20))),1,0)) -> 1 | AC20: =IF(OR($G20="",$AA20=""),"",IF(AND(ROUND($AA20,IF($E20="",3,$E20))>=ROUND($G20-$S20,IF($E20="",3,$E20)),ROUND($AA20,IF($E20="",3,$E20))<=ROUND($G20+$S20,IF($E20="",3,$E20))),1,0)) -> 1 | AD20: 11.3 | AE20: 17.3 | AF20: =IF(OR($F20="",$AD20=""),"",IF(AND(ROUND($AD20,IF($E20="",3,$E20))>=ROUND($F20-$O20,IF($E20="",3,$E20)),ROUND($AD20,IF($E20="",3,$E20))<=ROUND($F20+$O20,IF($E20="",3,$E20))),1,0)) -> 0 | AG20: =IF(OR($G20="",$AE20=""),"",IF(AND(ROUND($AE20,IF($E20="",3,$E20))>=ROUND($G20-$S20,IF($E20="",3,$E20)),ROUND($AE20,IF($E20="",3,$E20))<=ROUND($G20+$S20,IF($E20="",3,$E20))),1,0)) -> 1 | AH20: 10.9 | AI20: 17.5 | AJ20: =IF(OR($F20="",$AH20=""),"",IF(AND(ROUND($AH20,IF($E20="",3,$E20))>=ROUND($F20-$O20,IF($E20="",3,$E20)),ROUND($AH20,IF($E20="",3,$E20))<=ROUND($F20+$O20,IF($E20="",3,$E20))),1,0)) -> 1 | AK20: =IF(OR($G20="",$AI20=""),"",IF(AND(ROUND($AI20,IF($E20="",3,$E20))>=ROUND($G20-$S20,IF($E20="",3,$E20)),ROUND($AI20,IF($E20="",3,$E20))<=ROUND($G20+$S20,IF($E20="",3,$E20))),1,0)) -> 1 | AL20: 10.77 | AM20: 17.3 | AN20: =IF(OR($F20="",$AL20=""),"",IF(AND(ROUND($AL20,IF($E20="",3,$E20))>=ROUND($F20-$O20,IF($E20="",3,$E20)),ROUND($AL20,IF($E20="",3,$E20))<=ROUND($F20+$O20,IF($E20="",3,$E20))),1,0)) -> 1 | AO20: =IF(OR($G20="",$AM20=""),"",IF(AND(ROUND($AM20,IF($E20="",3,$E20))>=ROUND($G20-$S20,IF($E20="",3,$E20)),ROUND($AM20,IF($E20="",3,$E20))<=ROUND($G20+$S20,IF($E20="",3,$E20))),1,0)) -> 1 | AQ20: TML | AR20: =IFERROR((X24+Y24)/COUNT(X12:Y23),"") -> 0.66666667 | AS20: =IFERROR(IF(AR20="","",_xlfn.RANK.EQ(AR20,$AR$20:$AR$24)),"") -> 5 | AT20: =X24&"/"&COUNT(X12:X23) -> 7/12 | AU20: =Y24&"/"&COUNT(Y12:Y23) -> 9/12 | AV20: =(X24+Y24)&"/"&COUNT(X12:Y23) -> 16/24
B21: WBC | C21: 10^3/μL | D21: 992 | E21: 2 | F21: 3.16 | G21: 7.73 | H21: =IFERROR(SQRT(EXP(((LN(G21)-LN(IF(OR(F21="",F21=0),IF(G21="","",0.15*G21),F21)))/3.92)^2)-1),"") -> 0.23120148 | I21: =IFERROR(((SQRT(H21*100-0.25))/100),"") -> 0.047822743 | J21: =IFERROR(EXP((IF(OR(F21="",F21=0),LN(G21*0.15),LN(F21))+LN(G21))/2),"") -> 4.9423476 | K21: =IFERROR(I21*J21,"") -> 0.23635662 | L21: =IFERROR((K21-0.2*K21)/J21,"") -> 0.038258195 | M21: =IFERROR(0.2*K21,"") -> 0.047271324 | N21: =IFERROR(IF(F21="","",F21*L21+M21),"") -> 0.16816722 | O21: =IFERROR($G$8*N21,"") -> 0.27661046 | P21: =IFERROR(CONCATENATE(ROUND(F21-O21,IF(E21="",3,E21))," to ",ROUND(F21+O21,IF(E21="",3,E21))),"") -> 2,88 to 3,44 | R21: =IFERROR(IF(G21="","",G21*L21+M21),"") -> 0.34300717 | S21: =IFERROR($G$8*R21,"") -> 0.56419658 | T21: =IFERROR(CONCATENATE(ROUND(G21-S21,IF(E21="",3,E21))," to ",ROUND(G21+S21,IF(E21="",3,E21))),"") -> 7,17 to 8,29 | V21: 3.65 | W21: 7.77 | X21: =IF(OR($F21="",$V21=""),"",IF(AND(ROUND($V21,IF($E21="",3,$E21))>=ROUND($F21-$O21,IF($E21="",3,$E21)),ROUND($V21,IF($E21="",3,$E21))<=ROUND($F21+$O21,IF($E21="",3,$E21))),1,0)) -> 0 | Y21: =IF(OR($G21="",$W21=""),"",IF(AND(ROUND($W21,IF($E21="",3,$E21))>=ROUND($G21-$S21,IF($E21="",3,$E21)),ROUND($W21,IF($E21="",3,$E21))<=ROUND($G21+$S21,IF($E21="",3,$E21))),1,0)) -> 1 | Z21: 3.18 | AA21: 8.09 | AB21: =IF(OR($F21="",$Z21=""),"",IF(AND(ROUND($Z21,IF($E21="",3,$E21))>=ROUND($F21-$O21,IF($E21="",3,$E21)),ROUND($Z21,IF($E21="",3,$E21))<=ROUND($F21+$O21,IF($E21="",3,$E21))),1,0)) -> 1 | AC21: =IF(OR($G21="",$AA21=""),"",IF(AND(ROUND($AA21,IF($E21="",3,$E21))>=ROUND($G21-$S21,IF($E21="",3,$E21)),ROUND($AA21,IF($E21="",3,$E21))<=ROUND($G21+$S21,IF($E21="",3,$E21))),1,0)) -> 1 | AD21: 3.34 | AE21: 8.05 | AF21: =IF(OR($F21="",$AD21=""),"",IF(AND(ROUND($AD21,IF($E21="",3,$E21))>=ROUND($F21-$O21,IF($E21="",3,$E21)),ROUND($AD21,IF($E21="",3,$E21))<=ROUND($F21+$O21,IF($E21="",3,$E21))),1,0)) -> 1 | AG21: =IF(OR($G21="",$AE21=""),"",IF(AND(ROUND($AE21,IF($E21="",3,$E21))>=ROUND($G21-$S21,IF($E21="",3,$E21)),ROUND($AE21,IF($E21="",3,$E21))<=ROUND($G21+$S21,IF($E21="",3,$E21))),1,0)) -> 1 | AH21: 3.32 | AI21: 8.17 | AJ21: =IF(OR($F21="",$AH21=""),"",IF(AND(ROUND($AH21,IF($E21="",3,$E21))>=ROUND($F21-$O21,IF($E21="",3,$E21)),ROUND($AH21,IF($E21="",3,$E21))<=ROUND($F21+$O21,IF($E21="",3,$E21))),1,0)) -> 1 | AK21: =IF(OR($G21="",$AI21=""),"",IF(AND(ROUND($AI21,IF($E21="",3,$E21))>=ROUND($G21-$S21,IF($E21="",3,$E21)),ROUND($AI21,IF($E21="",3,$E21))<=ROUND($G21+$S21,IF($E21="",3,$E21))),1,0)) -> 1 | AL21: 3.25 | AM21: 8.15 | AN21: =IF(OR($F21="",$AL21=""),"",IF(AND(ROUND($AL21,IF($E21="",3,$E21))>=ROUND($F21-$O21,IF($E21="",3,$E21)),ROUND($AL21,IF($E21="",3,$E21))<=ROUND($F21+$O21,IF($E21="",3,$E21))),1,0)) -> 1 | AO21: =IF(OR($G21="",$AM21=""),"",IF(AND(ROUND($AM21,IF($E21="",3,$E21))>=ROUND($G21-$S21,IF($E21="",3,$E21)),ROUND($AM21,IF($E21="",3,$E21))<=ROUND($G21+$S21,IF($E21="",3,$E21))),1,0)) -> 1 | AQ21: refineR | AR21: =IFERROR((AB24+AC24)/COUNT(AB12:AC23),"") -> 0.75 | AS21: =IFERROR(IF(AR21="","",_xlfn.RANK.EQ(AR21,$AR$20:$AR$24)),"") -> 4 | AT21: =AB24&"/"&COUNT(AB12:AB23) -> 9/12 | AU21: =AC24&"/"&COUNT(AC12:AC23) -> 9/12 | AV21: =(AB24+AC24)&"/"&COUNT(AB12:AC23) -> 18/24
B22: LYM | C22: 10^3/μL | D22: 992 | E22: 2 | F22: 1.31 | G22: 3.38 | H22: =IFERROR(SQRT(EXP(((LN(G22)-LN(IF(OR(F22="",F22=0),IF(G22="","",0.15*G22),F22)))/3.92)^2)-1),"") -> 0.2453758 | I22: =IFERROR(((SQRT(H22*100-0.25))/100),"") -> 0.049282431 | J22: =IFERROR(EXP((IF(OR(F22="",F22=0),LN(G22*0.15),LN(F22))+LN(G22))/2),"") -> 2.1042338 | K22: =IFERROR(I22*J22,"") -> 0.10370176 | L22: =IFERROR((K22-0.2*K22)/J22,"") -> 0.039425944 | M22: =IFERROR(0.2*K22,"") -> 0.020740351 | N22: =IFERROR(IF(F22="","",F22*L22+M22),"") -> 0.072388339 | O22: =IFERROR($G$8*N22,"") -> 0.11906822 | P22: =IFERROR(CONCATENATE(ROUND(F22-O22,IF(E22="",3,E22))," to ",ROUND(F22+O22,IF(E22="",3,E22))),"") -> 1,19 to 1,43 | R22: =IFERROR(IF(G22="","",G22*L22+M22),"") -> 0.15400004 | S22: =IFERROR($G$8*R22,"") -> 0.25330753 | T22: =IFERROR(CONCATENATE(ROUND(G22-S22,IF(E22="",3,E22))," to ",ROUND(G22+S22,IF(E22="",3,E22))),"") -> 3,13 to 3,63 | V22: 0.96 | W22: 3.27 | X22: =IF(OR($F22="",$V22=""),"",IF(AND(ROUND($V22,IF($E22="",3,$E22))>=ROUND($F22-$O22,IF($E22="",3,$E22)),ROUND($V22,IF($E22="",3,$E22))<=ROUND($F22+$O22,IF($E22="",3,$E22))),1,0)) -> 0 | Y22: =IF(OR($G22="",$W22=""),"",IF(AND(ROUND($W22,IF($E22="",3,$E22))>=ROUND($G22-$S22,IF($E22="",3,$E22)),ROUND($W22,IF($E22="",3,$E22))<=ROUND($G22+$S22,IF($E22="",3,$E22))),1,0)) -> 1 | Z22: 1.31 | AA22: 3.58 | AB22: =IF(OR($F22="",$Z22=""),"",IF(AND(ROUND($Z22,IF($E22="",3,$E22))>=ROUND($F22-$O22,IF($E22="",3,$E22)),ROUND($Z22,IF($E22="",3,$E22))<=ROUND($F22+$O22,IF($E22="",3,$E22))),1,0)) -> 1 | AC22: =IF(OR($G22="",$AA22=""),"",IF(AND(ROUND($AA22,IF($E22="",3,$E22))>=ROUND($G22-$S22,IF($E22="",3,$E22)),ROUND($AA22,IF($E22="",3,$E22))<=ROUND($G22+$S22,IF($E22="",3,$E22))),1,0)) -> 1 | AD22: 1.36 | AE22: 3.41 | AF22: =IF(OR($F22="",$AD22=""),"",IF(AND(ROUND($AD22,IF($E22="",3,$E22))>=ROUND($F22-$O22,IF($E22="",3,$E22)),ROUND($AD22,IF($E22="",3,$E22))<=ROUND($F22+$O22,IF($E22="",3,$E22))),1,0)) -> 1 | AG22: =IF(OR($G22="",$AE22=""),"",IF(AND(ROUND($AE22,IF($E22="",3,$E22))>=ROUND($G22-$S22,IF($E22="",3,$E22)),ROUND($AE22,IF($E22="",3,$E22))<=ROUND($G22+$S22,IF($E22="",3,$E22))),1,0)) -> 1 | AH22: 1.36 | AI22: 3.61 | AJ22: =IF(OR($F22="",$AH22=""),"",IF(AND(ROUND($AH22,IF($E22="",3,$E22))>=ROUND($F22-$O22,IF($E22="",3,$E22)),ROUND($AH22,IF($E22="",3,$E22))<=ROUND($F22+$O22,IF($E22="",3,$E22))),1,0)) -> 1 | AK22: =IF(OR($G22="",$AI22=""),"",IF(AND(ROUND($AI22,IF($E22="",3,$E22))>=ROUND($G22-$S22,IF($E22="",3,$E22)),ROUND($AI22,IF($E22="",3,$E22))<=ROUND($G22+$S22,IF($E22="",3,$E22))),1,0)) -> 1 | AL22: 1.23 | AM22: 3.19 | AN22: =IF(OR($F22="",$AL22=""),"",IF(AND(ROUND($AL22,IF($E22="",3,$E22))>=ROUND($F22-$O22,IF($E22="",3,$E22)),ROUND($AL22,IF($E22="",3,$E22))<=ROUND($F22+$O22,IF($E22="",3,$E22))),1,0)) -> 1 | AO22: =IF(OR($G22="",$AM22=""),"",IF(AND(ROUND($AM22,IF($E22="",3,$E22))>=ROUND($G22-$S22,IF($E22="",3,$E22)),ROUND($AM22,IF($E22="",3,$E22))<=ROUND($G22+$S22,IF($E22="",3,$E22))),1,0)) -> 1 | AQ22: TMC | AR22: =IFERROR((AF24+AG24)/COUNT(AF12:AG23),"") -> 0.875 | AS22: =IFERROR(IF(AR22="","",_xlfn.RANK.EQ(AR22,$AR$20:$AR$24)),"") -> 3 | AT22: =AF24&"/"&COUNT(AF12:AF23) -> 10/12 | AU22: =AG24&"/"&COUNT(AG12:AG23) -> 11/12 | AV22: =(AF24+AG24)&"/"&COUNT(AF12:AG23) -> 21/24
B23: PLT | C23: 10^3/μL | D23: 992 | E23: 1 | F23: 140.2 | G23: 384 | H23: =IFERROR(SQRT(EXP(((LN(G23)-LN(IF(OR(F23="",F23=0),IF(G23="","",0.15*G23),F23)))/3.92)^2)-1),"") -> 0.26133816 | I23: =IFERROR(((SQRT(H23*100-0.25))/100),"") -> 0.05087614 | J23: =IFERROR(EXP((IF(OR(F23="",F23=0),LN(G23*0.15),LN(F23))+LN(G23))/2),"") -> 232.02758 | K23: =IFERROR(I23*J23,"") -> 11.804668 | L23: =IFERROR((K23-0.2*K23)/J23,"") -> 0.040700912 | M23: =IFERROR(0.2*K23,"") -> 2.3609336 | N23: =IFERROR(IF(F23="","",F23*L23+M23),"") -> 8.0672014 | O23: =IFERROR($G$8*N23,"") -> 13.269365 | P23: =IFERROR(CONCATENATE(ROUND(F23-O23,IF(E23="",3,E23))," to ",ROUND(F23+O23,IF(E23="",3,E23))),"") -> 126,9 to 153,5 | R23: =IFERROR(IF(G23="","",G23*L23+M23),"") -> 17.990084 | S23: =IFERROR($G$8*R23,"") -> 29.591054 | T23: =IFERROR(CONCATENATE(ROUND(G23-S23,IF(E23="",3,E23))," to ",ROUND(G23+S23,IF(E23="",3,E23))),"") -> 354,4 to 413,6 | V23: 115 | W23: 383 | X23: =IF(OR($F23="",$V23=""),"",IF(AND(ROUND($V23,IF($E23="",3,$E23))>=ROUND($F23-$O23,IF($E23="",3,$E23)),ROUND($V23,IF($E23="",3,$E23))<=ROUND($F23+$O23,IF($E23="",3,$E23))),1,0)) -> 0 | Y23: =IF(OR($G23="",$W23=""),"",IF(AND(ROUND($W23,IF($E23="",3,$E23))>=ROUND($G23-$S23,IF($E23="",3,$E23)),ROUND($W23,IF($E23="",3,$E23))<=ROUND($G23+$S23,IF($E23="",3,$E23))),1,0)) -> 1 | Z23: 139 | AA23: 385 | AB23: =IF(OR($F23="",$Z23=""),"",IF(AND(ROUND($Z23,IF($E23="",3,$E23))>=ROUND($F23-$O23,IF($E23="",3,$E23)),ROUND($Z23,IF($E23="",3,$E23))<=ROUND($F23+$O23,IF($E23="",3,$E23))),1,0)) -> 1 | AC23: =IF(OR($G23="",$AA23=""),"",IF(AND(ROUND($AA23,IF($E23="",3,$E23))>=ROUND($G23-$S23,IF($E23="",3,$E23)),ROUND($AA23,IF($E23="",3,$E23))<=ROUND($G23+$S23,IF($E23="",3,$E23))),1,0)) -> 1 | AD23: 148 | AE23: 362 | AF23: =IF(OR($F23="",$AD23=""),"",IF(AND(ROUND($AD23,IF($E23="",3,$E23))>=ROUND($F23-$O23,IF($E23="",3,$E23)),ROUND($AD23,IF($E23="",3,$E23))<=ROUND($F23+$O23,IF($E23="",3,$E23))),1,0)) -> 1 | AG23: =IF(OR($G23="",$AE23=""),"",IF(AND(ROUND($AE23,IF($E23="",3,$E23))>=ROUND($G23-$S23,IF($E23="",3,$E23)),ROUND($AE23,IF($E23="",3,$E23))<=ROUND($G23+$S23,IF($E23="",3,$E23))),1,0)) -> 1 | AH23: 125 | AI23: 381 | AJ23: =IF(OR($F23="",$AH23=""),"",IF(AND(ROUND($AH23,IF($E23="",3,$E23))>=ROUND($F23-$O23,IF($E23="",3,$E23)),ROUND($AH23,IF($E23="",3,$E23))<=ROUND($F23+$O23,IF($E23="",3,$E23))),1,0)) -> 0 | AK23: =IF(OR($G23="",$AI23=""),"",IF(AND(ROUND($AI23,IF($E23="",3,$E23))>=ROUND($G23-$S23,IF($E23="",3,$E23)),ROUND($AI23,IF($E23="",3,$E23))<=ROUND($G23+$S23,IF($E23="",3,$E23))),1,0)) -> 1 | AL23: 132 | AM23: 374 | AN23: =IF(OR($F23="",$AL23=""),"",IF(AND(ROUND($AL23,IF($E23="",3,$E23))>=ROUND($F23-$O23,IF($E23="",3,$E23)),ROUND($AL23,IF($E23="",3,$E23))<=ROUND($F23+$O23,IF($E23="",3,$E23))),1,0)) -> 1 | AO23: =IF(OR($G23="",$AM23=""),"",IF(AND(ROUND($AM23,IF($E23="",3,$E23))>=ROUND($G23-$S23,IF($E23="",3,$E23)),ROUND($AM23,IF($E23="",3,$E23))<=ROUND($G23+$S23,IF($E23="",3,$E23))),1,0)) -> 1 | AQ23: reflimR | AR23: =IFERROR((AJ24+AK24)/COUNT(AJ12:AK23),"") -> 0.95833333 | AS23: =IFERROR(IF(AR23="","",_xlfn.RANK.EQ(AR23,$AR$20:$AR$24)),"") -> 2 | AT23: =AJ24&"/"&COUNT(AJ12:AJ23) -> 11/12 | AU23: =AK24&"/"&COUNT(AK12:AK23) -> 12/12 | AV23: =(AJ24+AK24)&"/"&COUNT(AJ12:AK23) -> 23/24
V24: n TML LRL within EI | X24: =SUM(X12:X23) -> 7 | Y24: =SUM(Y12:Y23) -> 9 | Z24: n refineR RLs within EI | AB24: =SUM(AB12:AB23) -> 9 | AC24: =SUM(AC12:AC23) -> 9 | AD24: n TMC RLs within EI | AF24: =SUM(AF12:AF23) -> 10 | AG24: =SUM(AG12:AG23) -> 11 | AH24: n reflimR RLs within EI | AJ24: =SUM(AJ12:AJ23) -> 11 | AK24: =SUM(AK12:AK23) -> 12 | AL24: n LabRI RLs within EI | AN24: =SUM(AN12:AN23) -> 12 | AO24: =SUM(AO12:AO23) -> 12 | AQ24: LabRI | AR24: =IFERROR((AN24+AO24)/COUNT(AN12:AO23),"") -> 1 | AS24: =IFERROR(IF(AR24="","",_xlfn.RANK.EQ(AR24,$AR$20:$AR$24)),"") -> 1 | AT24: =AN24&"/"&COUNT(AN12:AN23) -> 12/12 | AU24: =AO24&"/"&COUNT(AO12:AO23) -> 12/12 | AV24: =(AN24+AO24)&"/"&COUNT(AN12:AO23) -> 24/24
V25: % TML LRL within EI | X25: =IFERROR(X24/COUNT(X12:X23),"") -> 0.58333333 | Y25: =IFERROR(Y24/COUNT(Y12:Y23),"") -> 0.75 | Z25: % refineR RLs within EI | AB25: =IFERROR(AB24/COUNT(AB12:AB23),"") -> 0.75 | AC25: =IFERROR(AC24/COUNT(AC12:AC23),"") -> 0.75 | AD25: % TMC RLs within EI | AF25: =IFERROR(AF24/COUNT(AF12:AF23),"") -> 0.83333333 | AG25: =IFERROR(AG24/COUNT(AG12:AG23),"") -> 0.91666667 | AH25: % reflimR RLs within EI | AJ25: =IFERROR(AJ24/COUNT(AJ12:AJ23),"") -> 0.91666667 | AK25: =IFERROR(AK24/COUNT(AK12:AK23),"") -> 1 | AL25: % LabRI RLs within EI | AN25: =IFERROR(AN24/COUNT(AN12:AN23),"") -> 1 | AO25: =IFERROR(AO24/COUNT(AO12:AO23),"") -> 1
V26: % TML RLs within EI (overall) | X26: {=IFERROR(SUM(X24:Y24/COUNT(X12:Y23)),"")} -> 0.66666667 | Z26: % refineR RLs within EI (overall) | AB26: =IFERROR(SUM(AB24:AC24)/COUNT(AB12:AC23),"") -> 0.75 | AD26: % TMC RLs within EI (overall) | AF26: =IFERROR(SUM(AF24:AG24)/COUNT(AF12:AG23),"") -> 0.875 | AH26: % reflimR RLs within EI (overall) | AJ26: =IFERROR(SUM(AJ24:AK24)/COUNT(AJ12:AK23),"") -> 0.95833333 | AL26: % LabRI RLs within EI (overall) | AN26: {=IFERROR(SUM(AN24:AO24/COUNT(AN12:AO23)),"")} -> 1
B28: Abbreviations:
B29: LRL: lower reference limit.
B30: URL: upper reference limit.
B31: CVE: empirical biological variation coefficient derived on the logarithmic scale from the reference interval. If the LRL is unknown, it is set at 15% of the URL for the CVE calculation.
B32: pCVA: the permissible analytical coefficient of variation (CVA) at the median on the linear scale, obtained from the CVE.
B33: Medln: median of the reference interval on the logarithmic scale.
B34: pSDA,Med: permissible analytical standard deviation (SDA) at the median of the reference interval.
B35: Slope: calculated from pSDA,Med and the median of the reference interval.
B36: Intercept: related to the limit of detection. Because the limit of detection is usually unknown for the human material matrix, 20% of pSDA,Med is applied empirically here as a surrogate.
B37: pSDA,LRL: permissible analytical standard deviation at the lower reference limit.
B38: pSDA,URL: permissible analytical standard deviation at the upper reference limit.
B39: pDLRL: permissible difference (pD) for the LRL, based on Haeckel's approach, which estimates the CVE from the reference interval provided by the user.
... B52: References
B53: 1 - R. Haeckel, T. Ammer, W. Wosniok, A. Krebs, A. Torge, M. Özcürümez, A. Bertram, Age-and sex-specific reference intervals of total cholesterol, LDL cholesterol, HDL cholesterol and non-HDL cholesterol. Comparison of two algorithms for the indirect estimation of reference intervals, Journal of Laboratory Medicine 47 (2023) 55–62. https://doi.org/10.1515/labmed-2022-0147. | O53: Link
B55: 2 - R. Haeckel, K. Adeli, G. Jones, K. Sikaris, W. Wosniok, Definitions and major prerequisites of direct and indirect approaches for estimating reference limits, Clinical Chemistry and Laboratory Medicine (CCLM) 61 (2023) 402–406. https://doi.org/10.1515/cclm-2022-1061. | O55: Link
B57: 4 - R. Haeckel, W. Wosniok, T. Streichert, Review of potentials and limitations of indirect approaches for estimating reference limits/intervals of quantitative procedures in laboratory medicine, Journal of Laboratory Medicine 45 (2021) 35–53. https://doi.org/10.1515/labmed-2020-0131. | O57: Link
B59: 5 - E. Gurr, R. Haeckel, M. Orth, T. Streichert, Festlegung der zulässigen Messunsicherheit quantitativer Messgrößen in der Laboratoriumsmedizin, LaboratoriumsMedizin 41 (2017) 53–58. https://doi.org/10.1515/labmed-2016-0079. | O59: Link
...

Sheet Input Group 2
D2: Performance Ranking by Index of Deviation of Reference Limits (PRIDe-RL)
D3: A multidimensional framework for comparative evaluation and ranking of reference-limit estimation methods
B5: Nominal coverage probability (or confidence level) | G5: 0.9 | P5: 0.8
B6: Significance level (α) | G6: =1-IF(G5="",0.9,G5) -> 0.1 | P6: 0.9
B7: ="Cumulative probability (quantile order, "&IF(G5="","1 − α/2",SUBSTITUTE(ROUND(1-(1-G5)/2,4)&"",",","."))&")" -> Cumulative probability (quantile order, 0.95) | G7: =1-G6/2 -> 0.95 | H7: Interpretation of the standard normal quantile
B8: {="Standard normal quantile (critical value, z"&IF(G5="","₁₋α/₂",_xlfn.LET(_xlpm.p,ROUND(1-(1-G5)/2,4),_xlpm.d,SUBSTITUTE(_xlpm.p&"",",","."),_xlfn.TEXTJOIN("",1,IFERROR(_xlfn.UNICHAR(8320+MID(_xlpm.d,_xlfn.SEQUENCE(LEN(_xlpm.d)),1)),"."))))&")"} -> Standard normal quantile (critical value, z₀.₉₅) | G8: =_xlfn.NORM.S.INV(G7) -> 1.6448536 | H8: {=_xlfn.LET(_xlpm.cl,IF(G5="",0.9,G5),_xlpm.p,ROUND(1-(1-_xlpm.cl)/2,4),_xlpm.d,SUBSTITUTE(_xlpm.p&"",",","."),_xlpm.sub,_xlfn.TEXTJOIN("",1,IFERROR(_xlfn.UNICHAR(8320+MID(_xlpm.d,_xlfn.SEQUENCE(LEN(_xlpm.d)),1)),".")),"where z"&_xlpm.sub&" = "&SUBSTITUTE(FIXED(_xlfn.NORM.S.INV(_xlpm.p),4,TRUE)&"",",",".")&" is the standard normal quantile corresponding to a two-sided nominal coverage probability of "&SUBSTITUTE(ROUND(_xlpm.cl*100,2)&"",",",".")&"%.")} -> where z₀.₉₅ = 1.6449 is the standard normal quantile corresponding to a two-sided nominal coverage probability of 90%.
B10: Test | C10: Unit | D10: n | E10: Decimal places | F10: Comparative Reference | H10: CVE | I10: pCVA | J10: Med | K10: pSDA,Med | L10: Slope | M10: Intercept | N10: pSDA,LRL | O10: pDLRL | P10: EILRL | R10: pSDA,URL | S10: pDURL | T10: EIURL | V10: TML | X10: TML LRL within EILRL | Y10: TML URL within EIURL | Z10: refineR | AB10: refineR LRL within EILRL | AC10: refineR URL within EIURL | AD10: TMC | AF10: TMC LRL within EILRL | AG10: TMC URL within EIURL | AH10: reflimR | AJ10: reflimR LRL within EILRL | AK10: reflimR URL within EIURL | AL10: LabRI | AN10: LabRI LRL within EILRL | AO10: LabRI URL within EIURL
F11: LRL | G11: URL | V11: LRL | W11: URL | X11: 1 = yes / 0 = no | Y11: 1 = yes / 0 = no | Z11: LRL | AA11: URL | AB11: 1 = yes / 0 = no | AC11: 1 = yes / 0 = no | AD11: LRL | AE11: URL | AF11: 1 = yes / 0 = no | AG11: 1 = yes / 0 = no | AH11: LRL | AI11: URL | AJ11: 1 = yes / 0 = no | AK11: 1 = yes / 0 = no | AL11: LRL | AM11: URL | AN11: 1 = yes / 0 = no | AO11: 1 = yes / 0 = no
B12: Testcase1 | C12: n/a | D12: 500 | E12: 1 | F12: 10.2 | G12: 29.8 | H12: =IFERROR(SQRT(EXP(((LN(G12)-LN(IF(OR(F12="",F12=0),IF(G12="","",0.15*G12),F12)))/3.92)^2)-1),"") -> 0.27869539 | I12: =IFERROR(((SQRT(H12*100-0.25))/100),"") -> 0.052554295 | J12: =IFERROR(EXP((IF(OR(F12="",F12=0),LN(G12*0.15),LN(F12))+LN(G12))/2),"") -> 17.434449 | K12: =IFERROR(I12*J12,"") -> 0.91625516 | L12: =IFERROR((K12-0.2*K12)/J12,"") -> 0.042043436 | M12: =IFERROR(0.2*K12,"") -> 0.18325103 | N12: =IFERROR(IF(F12="","",F12*L12+M12),"") -> 0.61209408 | O12: =IFERROR($G$8*N12,"") -> 1.0068052 | P12: =IFERROR(CONCATENATE(ROUND(F12-O12,IF(E12="",3,E12))," to ",ROUND(F12+O12,IF(E12="",3,E12))),"") -> 9,2 to 11,2 | R12: =IFERROR(IF(G12="","",G12*L12+M12),"") -> 1.4361454 | S12: =IFERROR($G$8*R12,"") -> 2.362249 | T12: =IFERROR(CONCATENATE(ROUND(G12-S12,IF(E12="",3,E12))," to ",ROUND(G12+S12,IF(E12="",3,E12))),"") -> 27,4 to 32,2 | V12: 12.1 | W12: 32.7 | X12: =IF(OR($F12="",$V12=""),"",IF(AND(ROUND($V12,IF($E12="",3,$E12))>=ROUND($F12-$O12,IF($E12="",3,$E12)),ROUND($V12,IF($E12="",3,$E12))<=ROUND($F12+$O12,IF($E12="",3,$E12))),1,0)) -> 0 | Y12: =IF(OR($G12="",$W12=""),"",IF(AND(ROUND($W12,IF($E12="",3,$E12))>=ROUND($G12-$S12,IF($E12="",3,$E12)),ROUND($W12,IF($E12="",3,$E12))<=ROUND($G12+$S12,IF($E12="",3,$E12))),1,0)) -> 0 | Z12: 11 | AA12: 31.2 | AB12: =IF(OR($F12="",$Z12=""),"",IF(AND(ROUND($Z12,IF($E12="",3,$E12))>=ROUND($F12-$O12,IF($E12="",3,$E12)),ROUND($Z12,IF($E12="",3,$E12))<=ROUND($F12+$O12,IF($E12="",3,$E12))),1,0)) -> 1 | AC12: =IF(OR($G12="",$AA12=""),"",IF(AND(ROUND($AA12,IF($E12="",3,$E12))>=ROUND($G12-$S12,IF($E12="",3,$E12)),ROUND($AA12,IF($E12="",3,$E12))<=ROUND($G12+$S12,IF($E12="",3,$E12))),1,0)) -> 1 | AD12: 10.4 | AE12: 30.3 | AF12: =IF(OR($F12="",$AD12=""),"",IF(AND(ROUND($AD12,IF($E12="",3,$E12))>=ROUND($F12-$O12,IF($E12="",3,$E12)),ROUND($AD12,IF($E12="",3,$E12))<=ROUND($F12+$O12,IF($E12="",3,$E12))),1,0)) -> 1 | AG12: =IF(OR($G12="",$AE12=""),"",IF(AND(ROUND($AE12,IF($E12="",3,$E12))>=ROUND($G12-$S12,IF($E12="",3,$E12)),ROUND($AE12,IF($E12="",3,$E12))<=ROUND($G12+$S12,IF($E12="",3,$E12))),1,0)) -> 1 | AH12: 11.2 | AI12: 29.9 | AJ12: =IF(OR($F12="",$AH12=""),"",IF(AND(ROUND($AH12,IF($E12="",3,$E12))>=ROUND($F12-$O12,IF($E12="",3,$E12)),ROUND($AH12,IF($E12="",3,$E12))<=ROUND($F12+$O12,IF($E12="",3,$E12))),1,0)) -> 1 | AK12: =IF(OR($G12="",$AI12=""),"",IF(AND(ROUND($AI12,IF($E12="",3,$E12))>=ROUND($G12-$S12,IF($E12="",3,$E12)),ROUND($AI12,IF($E12="",3,$E12))<=ROUND($G12+$S12,IF($E12="",3,$E12))),1,0)) -> 1 | AL12: 10.8 | AM12: 30 | AN12: =IF(OR($F12="",$AL12=""),"",IF(AND(ROUND($AL12,IF($E12="",3,$E12))>=ROUND($F12-$O12,IF($E12="",3,$E12)),ROUND($AL12,IF($E12="",3,$E12))<=ROUND($F12+$O12,IF($E12="",3,$E12))),1,0)) -> 1 | AO12: =IF(OR($G12="",$AM12=""),"",IF(AND(ROUND($AM12,IF($E12="",3,$E12))>=ROUND($G12-$S12,IF($E12="",3,$E12)),ROUND($AM12,IF($E12="",3,$E12))<=ROUND($G12+$S12,IF($E12="",3,$E12))),1,0)) -> 1
B13: Testcase1 | C13: n/a | D13: 1000 | E13: 1 | F13: 10.2 | G13: 29.8 | H13: =IFERROR(SQRT(EXP(((LN(G13)-LN(IF(OR(F13="",F13=0),IF(G13="","",0.15*G13),F13)))/3.92)^2)-1),"") -> 0.27869539 | I13: =IFERROR(((SQRT(H13*100-0.25))/100),"") -> 0.052554295 | J13: =IFERROR(EXP((IF(OR(F13="",F13=0),LN(G13*0.15),LN(F13))+LN(G13))/2),"") -> 17.434449 | K13: =IFERROR(I13*J13,"") -> 0.91625516 | L13: =IFERROR((K13-0.2*K13)/J13,"") -> 0.042043436 | M13: =IFERROR(0.2*K13,"") -> 0.18325103 | N13: =IFERROR(IF(F13="","",F13*L13+M13),"") -> 0.61209408 | O13: =IFERROR($G$8*N13,"") -> 1.0068052 | P13: =IFERROR(CONCATENATE(ROUND(F13-O13,IF(E13="",3,E13))," to ",ROUND(F13+O13,IF(E13="",3,E13))),"") -> 9,2 to 11,2 | R13: =IFERROR(IF(G13="","",G13*L13+M13),"") -> 1.4361454 | S13: =IFERROR($G$8*R13,"") -> 2.362249 | T13: =IFERROR(CONCATENATE(ROUND(G13-S13,IF(E13="",3,E13))," to ",ROUND(G13+S13,IF(E13="",3,E13))),"") -> 27,4 to 32,2 | V13: 11.3 | W13: 30.6 | X13: =IF(OR($F13="",$V13=""),"",IF(AND(ROUND($V13,IF($E13="",3,$E13))>=ROUND($F13-$O13,IF($E13="",3,$E13)),ROUND($V13,IF($E13="",3,$E13))<=ROUND($F13+$O13,IF($E13="",3,$E13))),1,0)) -> 0 | Y13: =IF(OR($G13="",$W13=""),"",IF(AND(ROUND($W13,IF($E13="",3,$E13))>=ROUND($G13-$S13,IF($E13="",3,$E13)),ROUND($W13,IF($E13="",3,$E13))<=ROUND($G13+$S13,IF($E13="",3,$E13))),1,0)) -> 1 | Z13: 11.5 | AA13: 30.9 | AB13: =IF(OR($F13="",$Z13=""),"",IF(AND(ROUND($Z13,IF($E13="",3,$E13))>=ROUND($F13-$O13,IF($E13="",3,$E13)),ROUND($Z13,IF($E13="",3,$E13))<=ROUND($F13+$O13,IF($E13="",3,$E13))),1,0)) -> 0 | AC13: =IF(OR($G13="",$AA13=""),"",IF(AND(ROUND($AA13,IF($E13="",3,$E13))>=ROUND($G13-$S13,IF($E13="",3,$E13)),ROUND($AA13,IF($E13="",3,$E13))<=ROUND($G13+$S13,IF($E13="",3,$E13))),1,0)) -> 1 | AD13: 10.5 | AE13: 29.7 | AF13: =IF(OR($F13="",$AD13=""),"",IF(AND(ROUND($AD13,IF($E13="",3,$E13))>=ROUND($F13-$O13,IF($E13="",3,$E13)),ROUND($AD13,IF($E13="",3,$E13))<=ROUND($F13+$O13,IF($E13="",3,$E13))),1,0)) -> 1 | AG13: =IF(OR($G13="",$AE13=""),"",IF(AND(ROUND($AE13,IF($E13="",3,$E13))>=ROUND($G13-$S13,IF($E13="",3,$E13)),ROUND($AE13,IF($E13="",3,$E13))<=ROUND($G13+$S13,IF($E13="",3,$E13))),1,0)) -> 1 | AH13: 12.1 | AI13: 36.8 | AJ13: =IF(OR($F13="",$AH13=""),"",IF(AND(ROUND($AH13,IF($E13="",3,$E13))>=ROUND($F13-$O13,IF($E13="",3,$E13)),ROUND($AH13,IF($E13="",3,$E13))<=ROUND($F13+$O13,IF($E13="",3,$E13))),1,0)) -> 0 | AK13: =IF(OR($G13="",$AI13=""),"",IF(AND(ROUND($AI13,IF($E13="",3,$E13))>=ROUND($G13-$S13,IF($E13="",3,$E13)),ROUND($AI13,IF($E13="",3,$E13))<=ROUND($G13+$S13,IF($E13="",3,$E13))),1,0)) -> 0 | AL13: 10.8 | AM13: 29.2 | AN13: =IF(OR($F13="",$AL13=""),"",IF(AND(ROUND($AL13,IF($E13="",3,$E13))>=ROUND($F13-$O13,IF($E13="",3,$E13)),ROUND($AL13,IF($E13="",3,$E13))<=ROUND($F13+$O13,IF($E13="",3,$E13))),1,0)) -> 1 | AO13: =IF(OR($G13="",$AM13=""),"",IF(AND(ROUND($AM13,IF($E13="",3,$E13))>=ROUND($G13-$S13,IF($E13="",3,$E13)),ROUND($AM13,IF($E13="",3,$E13))<=ROUND($G13+$S13,IF($E13="",3,$E13))),1,0)) -> 1
